WARNING: could not mount /etc/localtime: not a directory

========================================
WARNING: could not mount /etc/localtime: not a directory

========================================
WARNING: could not mount /etc/localtime: not a directory

========================================
WARNING: could not mount /etc/localtime: not a directory

========================================
WARNING: could not mount /etc/localtime: not a directory
/opt/ros/humble/lib/python3.10/site-packages/launch_ros/utilities/to_parameters_list.py:97: UserWarning: node name not provided to launch; parameter files will not apply
  warnings.warn(

========================================
WARNING: could not mount /etc/localtime: not a directory

========================================
WARNING: could not mount /etc/localtime: not a directory
Future exception was never retrieved
future: <Future finished exception=InvalidHandle('cannot use Destroyable because destruction was requested')>
Traceback (most recent call last):
  File "/usr/lib/python3.10/concurrent/futures/thread.py", line 58, in run
    result = self.fn(*self.args, **self.kwargs)
  File "/opt/ros/humble/lib/python3.10/site-packages/launch_ros/actions/load_composable_nodes.py", line 197, in _load_in_sequence
    self._load_node(next_load_node_request, context)
  File "/opt/ros/humble/lib/python3.10/site-packages/launch_ros/actions/load_composable_nodes.py", line 119, in _load_node
    while not self.__rclpy_load_node_client.wait_for_service(timeout_sec=1.0):
  File "/opt/ros/humble/local/lib/python3.10/dist-packages/rclpy/client.py", line 176, in wait_for_service
    while self.context.ok() and not self.service_is_ready() and timeout_sec > 0.0:
  File "/opt/ros/humble/local/lib/python3.10/dist-packages/rclpy/client.py", line 159, in service_is_ready
    with self.handle:
rclpy._rclpy_pybind11.InvalidHandle: cannot use Destroyable because destruction was requested

========================================
WARNING: could not mount /etc/localtime: not a directory
Future exception was never retrieved
future: <Future finished exception=InvalidHandle('cannot use Destroyable because destruction was requested')>
Traceback (most recent call last):
  File "/usr/lib/python3.10/concurrent/futures/thread.py", line 58, in run
    result = self.fn(*self.args, **self.kwargs)
  File "/opt/ros/humble/lib/python3.10/site-packages/launch_ros/actions/load_composable_nodes.py", line 197, in _load_in_sequence
    self._load_node(next_load_node_request, context)
  File "/opt/ros/humble/lib/python3.10/site-packages/launch_ros/actions/load_composable_nodes.py", line 119, in _load_node
    while not self.__rclpy_load_node_client.wait_for_service(timeout_sec=1.0):
  File "/opt/ros/humble/local/lib/python3.10/dist-packages/rclpy/client.py", line 180, in wait_for_service
    return self.service_is_ready()
  File "/opt/ros/humble/local/lib/python3.10/dist-packages/rclpy/client.py", line 159, in service_is_ready
    with self.handle:
rclpy._rclpy_pybind11.InvalidHandle: cannot use Destroyable because destruction was requested

========================================
WARNING: could not mount /etc/localtime: not a directory
Future exception was never retrieved
future: <Future finished exception=InvalidHandle('cannot use Destroyable because destruction was requested')>
Traceback (most recent call last):
  File "/usr/lib/python3.10/concurrent/futures/thread.py", line 58, in run
    result = self.fn(*self.args, **self.kwargs)
  File "/opt/ros/humble/lib/python3.10/site-packages/launch_ros/actions/load_composable_nodes.py", line 197, in _load_in_sequence
    self._load_node(next_load_node_request, context)
  File "/opt/ros/humble/lib/python3.10/site-packages/launch_ros/actions/load_composable_nodes.py", line 119, in _load_node
    while not self.__rclpy_load_node_client.wait_for_service(timeout_sec=1.0):
  File "/opt/ros/humble/local/lib/python3.10/dist-packages/rclpy/client.py", line 180, in wait_for_service
    return self.service_is_ready()
  File "/opt/ros/humble/local/lib/python3.10/dist-packages/rclpy/client.py", line 159, in service_is_ready
    with self.handle:
rclpy._rclpy_pybind11.InvalidHandle: cannot use Destroyable because destruction was requested

========================================
WARNING: could not mount /etc/localtime: not a directory
Future exception was never retrieved
future: <Future finished exception=InvalidHandle('cannot use Destroyable because destruction was requested')>
Traceback (most recent call last):
  File "/usr/lib/python3.10/concurrent/futures/thread.py", line 58, in run
    result = self.fn(*self.args, **self.kwargs)
  File "/opt/ros/humble/lib/python3.10/site-packages/launch_ros/actions/load_composable_nodes.py", line 197, in _load_in_sequence
    self._load_node(next_load_node_request, context)
  File "/opt/ros/humble/lib/python3.10/site-packages/launch_ros/actions/load_composable_nodes.py", line 119, in _load_node
    while not self.__rclpy_load_node_client.wait_for_service(timeout_sec=1.0):
  File "/opt/ros/humble/local/lib/python3.10/dist-packages/rclpy/client.py", line 180, in wait_for_service
    return self.service_is_ready()
  File "/opt/ros/humble/local/lib/python3.10/dist-packages/rclpy/client.py", line 159, in service_is_ready
    with self.handle:
rclpy._rclpy_pybind11.InvalidHandle: cannot use Destroyable because destruction was requested

========================================
WARNING: could not mount /etc/localtime: not a directory

========================================
WARNING: could not mount /etc/localtime: not a directory
/opt/ros/humble/lib/python3.10/site-packages/launch_ros/utilities/to_parameters_list.py:97: UserWarning: node name not provided to launch; parameter files will not apply
  warnings.warn(

========================================
WARNING: could not mount /etc/localtime: not a directory
Future exception was never retrieved
future: <Future finished exception=InvalidHandle('cannot use Destroyable because destruction was requested')>
Traceback (most recent call last):
  File "/usr/lib/python3.10/concurrent/futures/thread.py", line 58, in run
    result = self.fn(*self.args, **self.kwargs)
  File "/opt/ros/humble/lib/python3.10/site-packages/launch_ros/actions/load_composable_nodes.py", line 197, in _load_in_sequence
    self._load_node(next_load_node_request, context)
  File "/opt/ros/humble/lib/python3.10/site-packages/launch_ros/actions/load_composable_nodes.py", line 119, in _load_node
    while not self.__rclpy_load_node_client.wait_for_service(timeout_sec=1.0):
  File "/opt/ros/humble/local/lib/python3.10/dist-packages/rclpy/client.py", line 180, in wait_for_service
    return self.service_is_ready()
  File "/opt/ros/humble/local/lib/python3.10/dist-packages/rclpy/client.py", line 159, in service_is_ready
    with self.handle:
rclpy._rclpy_pybind11.InvalidHandle: cannot use Destroyable because destruction was requested

========================================
WARNING: could not mount /etc/localtime: not a directory
/opt/ros/humble/lib/python3.10/site-packages/launch_ros/utilities/to_parameters_list.py:97: UserWarning: node name not provided to launch; parameter files will not apply
  warnings.warn(

========================================
WARNING: could not mount /etc/localtime: not a directory

========================================
WARNING: could not mount /etc/localtime: not a directory
/opt/ros/humble/lib/python3.10/site-packages/launch_ros/utilities/to_parameters_list.py:97: UserWarning: node name not provided to launch; parameter files will not apply
  warnings.warn(

========================================
WARNING: could not mount /etc/localtime: not a directory
/opt/ros/humble/lib/python3.10/site-packages/launch_ros/utilities/to_parameters_list.py:97: UserWarning: node name not provided to launch; parameter files will not apply
  warnings.warn(
Future exception was never retrieved
future: <Future finished exception=InvalidHandle('cannot use Destroyable because destruction was requested')>
Traceback (most recent call last):
  File "/usr/lib/python3.10/concurrent/futures/thread.py", line 58, in run
    result = self.fn(*self.args, **self.kwargs)
  File "/opt/ros/humble/lib/python3.10/site-packages/launch_ros/actions/load_composable_nodes.py", line 197, in _load_in_sequence
    self._load_node(next_load_node_request, context)
  File "/opt/ros/humble/lib/python3.10/site-packages/launch_ros/actions/load_composable_nodes.py", line 119, in _load_node
    while not self.__rclpy_load_node_client.wait_for_service(timeout_sec=1.0):
  File "/opt/ros/humble/local/lib/python3.10/dist-packages/rclpy/client.py", line 176, in wait_for_service
    while self.context.ok() and not self.service_is_ready() and timeout_sec > 0.0:
  File "/opt/ros/humble/local/lib/python3.10/dist-packages/rclpy/client.py", line 159, in service_is_ready
    with self.handle:
rclpy._rclpy_pybind11.InvalidHandle: cannot use Destroyable because destruction was requested

========================================
WARNING: could not mount /etc/localtime: not a directory

========================================
WARNING: could not mount /etc/localtime: not a directory

========================================
WARNING: could not mount /etc/localtime: not a directory

========================================
WARNING: could not mount /etc/localtime: not a directory
Future exception was never retrieved
future: <Future finished exception=InvalidHandle('cannot use Destroyable because destruction was requested')>
Traceback (most recent call last):
  File "/usr/lib/python3.10/concurrent/futures/thread.py", line 58, in run
    result = self.fn(*self.args, **self.kwargs)
  File "/opt/ros/humble/lib/python3.10/site-packages/launch_ros/actions/load_composable_nodes.py", line 197, in _load_in_sequence
    self._load_node(next_load_node_request, context)
  File "/opt/ros/humble/lib/python3.10/site-packages/launch_ros/actions/load_composable_nodes.py", line 119, in _load_node
    while not self.__rclpy_load_node_client.wait_for_service(timeout_sec=1.0):
  File "/opt/ros/humble/local/lib/python3.10/dist-packages/rclpy/client.py", line 176, in wait_for_service
    while self.context.ok() and not self.service_is_ready() and timeout_sec > 0.0:
  File "/opt/ros/humble/local/lib/python3.10/dist-packages/rclpy/client.py", line 159, in service_is_ready
    with self.handle:
rclpy._rclpy_pybind11.InvalidHandle: cannot use Destroyable because destruction was requested

========================================
WARNING: could not mount /etc/localtime: not a directory
Future exception was never retrieved
future: <Future finished exception=InvalidHandle('cannot use Destroyable because destruction was requested')>
Traceback (most recent call last):
  File "/usr/lib/python3.10/concurrent/futures/thread.py", line 58, in run
    result = self.fn(*self.args, **self.kwargs)
  File "/opt/ros/humble/lib/python3.10/site-packages/launch_ros/actions/load_composable_nodes.py", line 197, in _load_in_sequence
    self._load_node(next_load_node_request, context)
  File "/opt/ros/humble/lib/python3.10/site-packages/launch_ros/actions/load_composable_nodes.py", line 119, in _load_node
    while not self.__rclpy_load_node_client.wait_for_service(timeout_sec=1.0):
  File "/opt/ros/humble/local/lib/python3.10/dist-packages/rclpy/client.py", line 176, in wait_for_service
    while self.context.ok() and not self.service_is_ready() and timeout_sec > 0.0:
  File "/opt/ros/humble/local/lib/python3.10/dist-packages/rclpy/client.py", line 159, in service_is_ready
    with self.handle:
rclpy._rclpy_pybind11.InvalidHandle: cannot use Destroyable because destruction was requested

========================================
WARNING: could not mount /etc/localtime: not a directory
/opt/ros/humble/lib/python3.10/site-packages/launch_ros/utilities/to_parameters_list.py:97: UserWarning: node name not provided to launch; parameter files will not apply
  warnings.warn(
Future exception was never retrieved
future: <Future finished exception=InvalidHandle('cannot use Destroyable because destruction was requested')>
Traceback (most recent call last):
  File "/usr/lib/python3.10/concurrent/futures/thread.py", line 58, in run
    result = self.fn(*self.args, **self.kwargs)
  File "/opt/ros/humble/lib/python3.10/site-packages/launch_ros/actions/load_composable_nodes.py", line 197, in _load_in_sequence
    self._load_node(next_load_node_request, context)
  File "/opt/ros/humble/lib/python3.10/site-packages/launch_ros/actions/load_composable_nodes.py", line 119, in _load_node
    while not self.__rclpy_load_node_client.wait_for_service(timeout_sec=1.0):
  File "/opt/ros/humble/local/lib/python3.10/dist-packages/rclpy/client.py", line 180, in wait_for_service
    return self.service_is_ready()
  File "/opt/ros/humble/local/lib/python3.10/dist-packages/rclpy/client.py", line 159, in service_is_ready
    with self.handle:
rclpy._rclpy_pybind11.InvalidHandle: cannot use Destroyable because destruction was requested

========================================
WARNING: could not mount /etc/localtime: not a directory

========================================
WARNING: could not mount /etc/localtime: not a directory

========================================
WARNING: could not mount /etc/localtime: not a directory
Future exception was never retrieved
future: <Future finished exception=InvalidHandle('cannot use Destroyable because destruction was requested')>
Traceback (most recent call last):
  File "/usr/lib/python3.10/concurrent/futures/thread.py", line 58, in run
    result = self.fn(*self.args, **self.kwargs)
  File "/opt/ros/humble/lib/python3.10/site-packages/launch_ros/actions/load_composable_nodes.py", line 197, in _load_in_sequence
    self._load_node(next_load_node_request, context)
  File "/opt/ros/humble/lib/python3.10/site-packages/launch_ros/actions/load_composable_nodes.py", line 119, in _load_node
    while not self.__rclpy_load_node_client.wait_for_service(timeout_sec=1.0):
  File "/opt/ros/humble/local/lib/python3.10/dist-packages/rclpy/client.py", line 180, in wait_for_service
    return self.service_is_ready()
  File "/opt/ros/humble/local/lib/python3.10/dist-packages/rclpy/client.py", line 159, in service_is_ready
    with self.handle:
rclpy._rclpy_pybind11.InvalidHandle: cannot use Destroyable because destruction was requested

========================================
WARNING: could not mount /etc/localtime: not a directory

========================================
WARNING: could not mount /etc/localtime: not a directory
/opt/ros/humble/lib/python3.10/site-packages/launch_ros/utilities/to_parameters_list.py:97: UserWarning: node name not provided to launch; parameter files will not apply
  warnings.warn(

========================================
WARNING: could not mount /etc/localtime: not a directory
/opt/ros/humble/lib/python3.10/site-packages/launch_ros/utilities/to_parameters_list.py:97: UserWarning: node name not provided to launch; parameter files will not apply
  warnings.warn(

========================================
WARNING: could not mount /etc/localtime: not a directory
Future exception was never retrieved
future: <Future finished exception=InvalidHandle('cannot use Destroyable because destruction was requested')>
Traceback (most recent call last):
  File "/usr/lib/python3.10/concurrent/futures/thread.py", line 58, in run
    result = self.fn(*self.args, **self.kwargs)
  File "/opt/ros/humble/lib/python3.10/site-packages/launch_ros/actions/load_composable_nodes.py", line 197, in _load_in_sequence
    self._load_node(next_load_node_request, context)
  File "/opt/ros/humble/lib/python3.10/site-packages/launch_ros/actions/load_composable_nodes.py", line 119, in _load_node
    while not self.__rclpy_load_node_client.wait_for_service(timeout_sec=1.0):
  File "/opt/ros/humble/local/lib/python3.10/dist-packages/rclpy/client.py", line 180, in wait_for_service
    return self.service_is_ready()
  File "/opt/ros/humble/local/lib/python3.10/dist-packages/rclpy/client.py", line 159, in service_is_ready
    with self.handle:
rclpy._rclpy_pybind11.InvalidHandle: cannot use Destroyable because destruction was requested
Future exception was never retrieved
future: <Future finished exception=InvalidHandle('cannot use Destroyable because destruction was requested')>
Traceback (most recent call last):
  File "/usr/lib/python3.10/concurrent/futures/thread.py", line 58, in run
    result = self.fn(*self.args, **self.kwargs)
  File "/opt/ros/humble/lib/python3.10/site-packages/launch_ros/actions/load_composable_nodes.py", line 197, in _load_in_sequence
    self._load_node(next_load_node_request, context)
  File "/opt/ros/humble/lib/python3.10/site-packages/launch_ros/actions/load_composable_nodes.py", line 119, in _load_node
    while not self.__rclpy_load_node_client.wait_for_service(timeout_sec=1.0):
  File "/opt/ros/humble/local/lib/python3.10/dist-packages/rclpy/client.py", line 180, in wait_for_service
    return self.service_is_ready()
  File "/opt/ros/humble/local/lib/python3.10/dist-packages/rclpy/client.py", line 159, in service_is_ready
    with self.handle:
rclpy._rclpy_pybind11.InvalidHandle: cannot use Destroyable because destruction was requested

========================================
WARNING: could not mount /etc/localtime: not a directory

========================================
WARNING: could not mount /etc/localtime: not a directory

========================================
WARNING: could not mount /etc/localtime: not a directory

========================================
WARNING: could not mount /etc/localtime: not a directory
Future exception was never retrieved
future: <Future finished exception=InvalidHandle('cannot use Destroyable because destruction was requested')>
Traceback (most recent call last):
  File "/usr/lib/python3.10/concurrent/futures/thread.py", line 58, in run
    result = self.fn(*self.args, **self.kwargs)
  File "/opt/ros/humble/lib/python3.10/site-packages/launch_ros/actions/load_composable_nodes.py", line 197, in _load_in_sequence
    self._load_node(next_load_node_request, context)
  File "/opt/ros/humble/lib/python3.10/site-packages/launch_ros/actions/load_composable_nodes.py", line 119, in _load_node
    while not self.__rclpy_load_node_client.wait_for_service(timeout_sec=1.0):
  File "/opt/ros/humble/local/lib/python3.10/dist-packages/rclpy/client.py", line 180, in wait_for_service
    return self.service_is_ready()
  File "/opt/ros/humble/local/lib/python3.10/dist-packages/rclpy/client.py", line 159, in service_is_ready
    with self.handle:
rclpy._rclpy_pybind11.InvalidHandle: cannot use Destroyable because destruction was requested

========================================
WARNING: could not mount /etc/localtime: not a directory
Future exception was never retrieved
future: <Future finished exception=InvalidHandle('cannot use Destroyable because destruction was requested')>
Traceback (most recent call last):
  File "/usr/lib/python3.10/concurrent/futures/thread.py", line 58, in run
    result = self.fn(*self.args, **self.kwargs)
  File "/opt/ros/humble/lib/python3.10/site-packages/launch_ros/actions/load_composable_nodes.py", line 197, in _load_in_sequence
    self._load_node(next_load_node_request, context)
  File "/opt/ros/humble/lib/python3.10/site-packages/launch_ros/actions/load_composable_nodes.py", line 119, in _load_node
    while not self.__rclpy_load_node_client.wait_for_service(timeout_sec=1.0):
  File "/opt/ros/humble/local/lib/python3.10/dist-packages/rclpy/client.py", line 180, in wait_for_service
    return self.service_is_ready()
  File "/opt/ros/humble/local/lib/python3.10/dist-packages/rclpy/client.py", line 159, in service_is_ready
    with self.handle:
rclpy._rclpy_pybind11.InvalidHandle: cannot use Destroyable because destruction was requested

========================================

We trust you have received the usual lecture from the local System
Administrator. It usually boils down to these three things:

    #1) Respect the privacy of others.
    #2) Think before you type.
    #3) With great power comes great responsibility.

sudo: no tty present and no askpass program specified

========================================
